Workbook

Sheet Read Me
A1: GreenThreads Operations — Denver Launch Readiness (v2)
A3: HW#3 Data Intelligence Project — supporting analysis. Revised with cross-department source data.
A4: Company: GreenThreads | Function: Operations | Analysis date (As_of_Date): August 18, 2026
A5: Function goal (HW#1): get the four launch products onto the Denver sales floor on time.
A7: What changed in v2
A8: v1 analyzed supplier reliability against an October 12 opening treated as fixed. Finance and HR source
A9: documents show that date is not established anywhere: the lease build-out window ends Oct 13-27, and no
A10: document in any department states a required in-store date. Timeline risk is now the lead finding, with
A11: supplier reliability as the exposure that rides on it.
A13: Tabs
A14: Data Dictionary — every field defined and classified, with its quality rule.
A15: Cleaning & Validation — every check run, its result, treatment, and business reason.
... A44: every trigger and makes the final decision.

Sheet Data Dictionary
A1: Data Dictionary
A2: Field meanings confirmed before analysis. Classification separates inputs, calculated outcomes, and validation fields.
A4: Dataset | B4: Field | C4: Business definition | D4: Type | E4: Classification | F4: Quality rule
A5: Shipments | B5: PO_Number | C5: Unique purchase-order identifier. | D5: Text | E5: Identifier | F5: Required; unique; PO-#### format
A6: Shipments | B6: SKU | C6: Stock-keeping unit identifier. | D6: Text | E6: Identifier | F6: Required; maps to one catalog product
A7: Shipments | B7: Supplier | C7: Vendor responsible for the shipment. | D7: Text | E7: Dimension | F7: One spelling; maps to one country
A8: Shipments | B8: Promised_Date | C8: Supplier-planned receipt date. | D8: Date | E8: Input | F8: Must be >= order date
A9: Shipments | B9: Actual_Receipt_Date | C9: Actual receipt; legitimately blank while in transit. | D9: Date | E9: Outcome | F9: Required only when Received
A10: Shipments | B10: Status | C10: Received or In transit. | D10: Text | E10: Status | F10: Must agree with receipt-date presence
A11: Shipments | B11: Days_Late | C11: Actual minus promised. Blank while in transit. | D11: Number | E11: Calculated outcome | F11: Recalculate and match
A12: Shipments | B12: Line_Cost | C12: Units multiplied by unit cost. | D12: Currency | E12: Calculated | F12: Must reconcile
A13: Derived | B13: Current_Days_Overdue | C13: Days past promise for an in-transit order as of As_of_Date. | D13: Number | E13: Calculated | F13: Never replace unknown receipt with zero
A14: Catalog | B14: Lead_Time_Days | C14: Planned supplier lead time. | D14: Integer | E14: Input | F14: Order_By + Lead_Time implies in-store date
A15: Catalog | B15: Units_Per_Carton | C15: Units in a full shipping carton. | D15: Integer | E15: Constraint | F15: Launch buy should be a whole multiple
... A23: HR | B23: Offer_Accepted | C23: Whether an extended offer was accepted. | D23: Text | E23: Outcome | F23: Drives staffing coverage risk

Sheet Cleaning & Validation
A1: Cleaning & Validation
A2: Issues documented transparently. Valid blanks preserved as unknowns; no source values silently changed.
A4: # | B4: Check | C4: Result | D4: Status | E4: Treatment | F4: Business reason
A5: 1 | B5: Shipment row count | C5: 96 rows present | D5: Pass | E5: Retained | F5: Complete analysis population
A6: 2 | B6: Duplicate PO numbers | C6: 0 duplicates (PO-4400 to PO-4495) | D6: Pass | E6: No removal needed | F6: Avoids double counting
A7: 3 | B7: Required shipment fields | C7: 0 missing required fields | D7: Pass | E7: No correction needed | F7: Inputs complete
A8: 4 | B8: Date logic (order <= promised) | C8: 0 invalid sequences | D8: Pass | E8: No correction needed | F8: Prevents negative lead-time errors
A9: 5 | B9: Status / receipt consistency | C9: 0 conflicts | D9: Pass | E9: No correction needed | F9: Status controls eligible calculations
A10: 6 | B10: Line-cost reconciliation | C10: 0 mismatches | D10: Pass | E10: No correction needed | F10: Protects cost totals
A11: 7 | B11: Days_Late recalculation | C11: 0 mismatches across 80 received rows | D11: Pass | E11: No correction needed | F11: Verifies AI-reported delay math
A12: 8 | B12: Cross-file catalog mapping | C12: 0 mapping or economics mismatches | D12: Pass | E12: No correction needed | F12: SKU, supplier, cost reconcile
A13: 9 | B13: Valid in-transit blanks | C13: 32 blanks across 16 rows | D13: Expected | E13: Preserved; measured against As_of_Date | F13: An unknown receipt is not an on-time receipt
A14: 10 | B14: Supplier name consistency | C14: 4 suppliers, 1 spelling each in this file | D14: Pass (watch) | E14: Normalization retained in pipeline | F14: An earlier export split one supplier across two spellings
A15: 11 | B15: Launch carton multiples | C15: 3 of 4 buys are not whole cartons (70.8, 66.7, 59.4) | D15: Needs verification | E15: Escalated for confirmation; source unchanged | F15: Avoids receiving disputes at the dock
... A20: 16 | B20: Required in-store date | C20: Not stated in any Operations, Finance, or HR document reviewed | D20: Open gap | E20: Escalated to Store Manager | F20: OPS-04 step 1 cannot be executed without it

Sheet Timeline Reconciliation
A1: Timeline Reconciliation — four departments, four dates
A2: Every date below is read directly from a source document. The conflict is the finding.
A4: Source | B4: Department | C4: What it establishes | D4: Implied date | E4: Status
A5: SKU catalog: Order_By + Lead_Time | B5: Operations | C5: All four launch SKUs are planned to land on one date | D5: October 12, 2026 | E5: Planning assumption
A6: Lease §3.1 Delivery | B6: Finance/Legal | C6: Landlord delivers tenant-ready 'on or about' Sept 1 | D6: September 1, 2026 | E6: Soft date, no penalty
A7: Lease §3.4 Build-out | B7: Finance/Legal | C7: Build-out customarily requires 6-8 weeks after delivery | D7: October 13 - 27, 2026 | E7: Earliest open is Oct 13
A8: Lease §4.2 Rent commencement | B8: Finance/Legal | C8: Rent starts on earlier of opening or 60 days after delivery | D8: October 31, 2026 | E8: Hard financial deadline
A9: HR offer letters + handbook 3.3 | B9: HR | C9: Sales Associates start Sept 28; 2 weeks paid training required | D9: October 12, 2026 | E9: Zero slack; staffing incomplete
A10: SH-2291 promise + Song Hong history | B10: Operations | C10: Oct 3 promise plus 12.1-day historical mean | D10: ~October 15, 2026 | E10: Planning inference
A11: Required in-store date | B11: Not found | C11: OPS-04 step 1 requires it; no document states it | D11: NOT ESTABLISHED | E11: Open gap
A13: The conflict: the earliest date the lease's own build-out window allows is October 13, one day after the October 12 date that Operations inventory planning, HR training, and the launch schedule are all built on. October 12 is not a tight date; it sits outside the lease's stated window. No document anywhere establishes a required in-store date, so the SOP's first planning step cannot be completed.

Sheet Shipments Data
A1: PO_Number | B1: SKU | C1: Product_Name | D1: Supplier | E1: Supplier_Country | F1: Destination_Store | G1: Order_Date | H1: Promised_Date | I1: Actual_Receipt_Date | J1: Status | K1: Days_Late | L1: Units | M1: Unit_Cost | N1: Line_Cost
A2: PO-4400 | B2: GT-CHN-07 | C2: Slim Chino | D2: Mekong Textile Co. | E2: Vietnam | F2: Boise | G2: 46064 | H2: 46124 | I2: 46132 | J2: Received | K2: 8 | L2: 400 | M2: 26 | N2: 10400
A3: PO-4401 | B3: GT-JKT-08 | C3: Recycled Denim Jacket | D3: Andes Knitworks | E3: Colombia | F3: Spokane | G3: 46007 | H3: 46037 | I3: 46037 | J3: Received | K3: 0 | L3: 600 | M3: 46 | N3: 27600
A4: PO-4402 | B4: GT-JOG-03 | C4: Bamboo Joggers | D4: Song Hong Apparel | E4: Vietnam | F4: Portland-Division | G4: 46162 | H4: 46227 | J4: In transit | L4: 600 | M4: 30 | N4: 18000
A5: PO-4403 | B5: GT-JOG-03 | C5: Bamboo Joggers | D5: Song Hong Apparel | E5: Vietnam | F5: Tacoma | G5: 46027 | H5: 46092 | I5: 46105 | J5: Received | K5: 13 | L5: 200 | M5: 30 | N5: 6000
A6: PO-4404 | B6: GT-TNK-06 | C6: Organic Tank Top | D6: Delta Organics | E6: India | F6: Eugene | G6: 46186 | H6: 46231 | J6: In transit | L6: 250 | M6: 11 | N6: 2750
A7: PO-4405 | B7: GT-POL-05 | C7: Performance Polo | D7: Delta Organics | E7: India | F7: Tacoma | G7: 46102 | H7: 46147 | I7: 46147 | J7: Received | K7: 0 | L7: 150 | M7: 19.5 | N7: 2925
A8: PO-4406 | B8: GT-POL-05 | C8: Performance Polo | D8: Delta Organics | E8: India | F8: Spokane | G8: 46130 | H8: 46175 | I8: 46175 | J8: Received | K8: 0 | L8: 500 | M8: 19.5 | N8: 9750
A9: PO-4407 | B9: GT-JOG-03 | C9: Bamboo Joggers | D9: Song Hong Apparel | E9: Vietnam | F9: Seattle-Cap Hill | G9: 46111 | H9: 46176 | I9: 46187 | J9: Received | K9: 11 | L9: 250 | M9: 30 | N9: 7500
A10: PO-4408 | B10: GT-JKT-08 | C10: Recycled Denim Jacket | D10: Andes Knitworks | E10: Colombia | F10: Austin-South Congress | G10: 46109 | H10: 46139 | I10: 46140 | J10: Received | K10: 1 | L10: 500 | M10: 46 | N10: 23000
A11: PO-4409 | B11: GT-SHT-02 | C11: Active Shorts | D11: Mekong Textile Co. | E11: Vietnam | F11: Tacoma | G11: 46169 | H11: 46229 | J11: In transit | L11: 500 | M11: 22 | N11: 11000
A12: PO-4410 | B12: GT-JOG-03 | C12: Bamboo Joggers | D12: Song Hong Apparel | E12: Vietnam | F12: Salt Lake City | G12: 46059 | H12: 46124 | I12: 46137 | J12: Received | K12: 13 | L12: 250 | M12: 30 | N12: 7500
A13: PO-4411 | B13: GT-TNK-06 | C13: Organic Tank Top | D13: Delta Organics | E13: India | F13: Spokane | G13: 46017 | H13: 46062 | I13: 46063 | J13: Received | K13: 1 | L13: 600 | M13: 11 | N13: 6600
A14: PO-4412 | B14: GT-SHT-02 | C14: Active Shorts | D14: Mekong Textile Co. | E14: Vietnam | F14: Bend | G14: 46101 | H14: 46161 | I14: 46173 | J14: Received | K14: 12 | L14: 400 | M14: 22 | N14: 8800
A15: PO-4413 | B15: GT-POL-05 | C15: Performance Polo | D15: Delta Organics | E15: India | F15: Boulder | G15: 46165 | H15: 46210 | I15: 46210 | J15: Received | K15: 0 | L15: 400 | M15: 19.5 | N15: 7800
A16: PO-4414 | B16: GT-JOG-03 | C16: Bamboo Joggers | D16: Song Hong Apparel | E16: Vietnam | F16: Boise | G16: 46063 | H16: 46128 | I16: 46139 | J16: Received | K16: 11 | L16: 150 | M16: 30 | N16: 4500
A17: PO-4415 | B17: GT-SHT-02 | C17: Active Shorts | D17: Mekong Textile Co. | E17: Vietnam | F17: Boulder | G17: 46122 | H17: 46182 | I17: 46188 | J17: Received | K17: 6 | L17: 300 | M17: 22 | N17: 6600
A18: PO-4416 | B18: GT-CHN-07 | C18: Slim Chino | D18: Mekong Textile Co. | E18: Vietnam | F18: Tacoma | G18: 46118 | H18: 46178 | I18: 46183 | J18: Received | K18: 5 | L18: 250 | M18: 26 | N18: 6500
A19: PO-4417 | B19: GT-JOG-03 | C19: Bamboo Joggers | D19: Song Hong Apparel | E19: Vietnam | F19: Seattle-Ballard | G19: 46007 | H19: 46072 | I19: 46079 | J19: Received | K19: 7 | L19: 200 | M19: 30 | N19: 6000
A20: PO-4418 | B20: GT-JOG-03 | C20: Bamboo Joggers | D20: Song Hong Apparel | E20: Vietnam | F20: Seattle-Cap Hill | G20: 46029 | H20: 46094 | I20: 46113 | J20: Received | K20: 19 | L20: 600 | M20: 30 | N20: 18000
A21: PO-4419 | B21: GT-JOG-03 | C21: Bamboo Joggers | D21: Song Hong Apparel | E21: Vietnam | F21: Bend | G21: 46187 | H21: 46252 | J21: In transit | L21: 250 | M21: 30 | N21: 7500
A22: PO-4420 | B22: GT-HOD-04 | C22: EcoFleece Hoodie | D22: Andes Knitworks | E22: Colombia | F22: Boulder | G22: 46102 | H22: 46132 | I22: 46132 | J22: Received | K22: 0 | L22: 400 | M22: 38 | N22: 15200
A23: PO-4421 | B23: GT-CHN-07 | C23: Slim Chino | D23: Mekong Textile Co. | E23: Vietnam | F23: Seattle-Cap Hill | G23: 46178 | H23: 46238 | J23: In transit | L23: 400 | M23: 26 | N23: 10400
A24: PO-4422 | B24: GT-SHT-02 | C24: Active Shorts | D24: Mekong Textile Co. | E24: Vietnam | F24: Boise | G24: 46142 | H24: 46202 | I24: 46207 | J24: Received | K24: 5 | L24: 400 | M24: 22 | N24: 8800
A25: PO-4423 | B25: GT-HOD-04 | C25: EcoFleece Hoodie | D25: Andes Knitworks | E25: Colombia | F25: Boulder | G25: 46018 | H25: 46048 | I25: 46048 | J25: Received | K25: 0 | L25: 250 | M25: 38 | N25: 9500
A26: PO-4424 | B26: GT-JKT-08 | C26: Recycled Denim Jacket | D26: Andes Knitworks | E26: Colombia | F26: Spokane | G26: 46065 | H26: 46095 | I26: 46096 | J26: Received | K26: 1 | L26: 200 | M26: 46 | N26: 9200
A27: PO-4425 | B27: GT-CHN-07 | C27: Slim Chino | D27: Mekong Textile Co. | E27: Vietnam | F27: Bend | G27: 46035 | H27: 46095 | I27: 46101 | J27: Received | K27: 6 | L27: 200 | M27: 26 | N27: 5200
A28: PO-4426 | B28: GT-HOD-04 | C28: EcoFleece Hoodie | D28: Andes Knitworks | E28: Colombia | F28: Spokane | G28: 46142 | H28: 46172 | I28: 46173 | J28: Received | K28: 1 | L28: 150 | M28: 38 | N28: 5700
A29: PO-4427 | B29: GT-HOD-04 | C29: EcoFleece Hoodie | D29: Andes Knitworks | E29: Colombia | F29: Seattle-Cap Hill | G29: 46091 | H29: 46121 | I29: 46122 | J29: Received | K29: 1 | L29: 200 | M29: 38 | N29: 7600
A30: PO-4428 | B30: GT-HOD-04 | C30: EcoFleece Hoodie | D30: Andes Knitworks | E30: Colombia | F30: Tacoma | G30: 46081 | H30: 46111 | I30: 46112 | J30: Received | K30: 1 | L30: 250 | M30: 38 | N30: 9500
A31: PO-4429 | B31: GT-POL-05 | C31: Performance Polo | D31: Delta Organics | E31: India | F31: Portland-Pearl | G31: 46170 | H31: 46215 | I31: 46217 | J31: Received | K31: 2 | L31: 400 | M31: 19.5 | N31: 7800
A32: PO-4430 | B32: GT-JKT-08 | C32: Recycled Denim Jacket | D32: Andes Knitworks | E32: Colombia | F32: Seattle-Cap Hill | G32: 46032 | H32: 46062 | I32: 46062 | J32: Received | K32: 0 | L32: 300 | M32: 46 | N32: 13800
A33: PO-4431 | B33: GT-TEE-01 | C33: Classic Tee | D33: Delta Organics | E33: India | F33: Boise | G33: 46161 | H33: 46206 | I33: 46207 | J33: Received | K33: 1 | L33: 500 | M33: 14.25 | N33: 7125
A34: PO-4432 | B34: GT-JOG-03 | C34: Bamboo Joggers | D34: Song Hong Apparel | E34: Vietnam | F34: Portland-Division | G34: 46087 | H34: 46152 | I34: 46169 | J34: Received | K34: 17 | L34: 500 | M34: 30 | N34: 15000
A35: PO-4433 | B35: GT-SHT-02 | C35: Active Shorts | D35: Mekong Textile Co. | E35: Vietnam | F35: Austin-South Congress | G35: 46167 | H35: 46227 | J35: In transit | L35: 200 | M35: 22 | N35: 4400
A36: PO-4434 | B36: GT-HOD-04 | C36: EcoFleece Hoodie | D36: Andes Knitworks | E36: Colombia | F36: Eugene | G36: 46057 | H36: 46087 | I36: 46087 | J36: Received | K36: 0 | L36: 250 | M36: 38 | N36: 9500
A37: PO-4435 | B37: GT-JOG-03 | C37: Bamboo Joggers | D37: Song Hong Apparel | E37: Vietnam | F37: Eugene | G37: 46054 | H37: 46119 | I37: 46130 | J37: Received | K37: 11 | L37: 400 | M37: 30 | N37: 12000
A38: PO-4436 | B38: GT-POL-05 | C38: Performance Polo | D38: Delta Organics | E38: India | F38: Boise | G38: 46057 | H38: 46102 | I38: 46102 | J38: Received | K38: 0 | L38: 250 | M38: 19.5 | N38: 4875
A39: PO-4437 | B39: GT-TEE-01 | C39: Classic Tee | D39: Delta Organics | E39: India | F39: Austin-South Congress | G39: 46079 | H39: 46124 | I39: 46124 | J39: Received | K39: 0 | L39: 250 | M39: 14.25 | N39: 3562.5
A40: PO-4438 | B40: GT-CHN-07 | C40: Slim Chino | D40: Mekong Textile Co. | E40: Vietnam | F40: Spokane | G40: 46102 | H40: 46162 | I40: 46174 | J40: Received | K40: 12 | L40: 250 | M40: 26 | N40: 6500
...

Sheet SKU Catalog
A1: SKU | B1: Product_Name | C1: Category | D1: Material | E1: Sustainability_Cert | F1: Supplier | G1: Supplier_Country | H1: Lead_Time_Days | I1: MOQ_Units | J1: Wholesale_Cost | K1: MSRP | L1: Unit_Margin | M1: Margin_Pct | N1: Units_Per_Carton | O1: In_Denver_Launch | P1: Denver_Opening_Buy_Units | Q1: Opening_Buy_Cost | R1: Opening_Buy_Retail_Value | S1: Order_By_Date | T1: Days_Until_Order_Deadline | U1: Notes
A2: GT-HOD-04 | B2: EcoFleece Hoodie | C2: Outerwear | D2: Recycled fleece | E2: GRS | F2: Andes Knitworks | G2: Colombia | H2: 30 | I2: 200 | J2: 38 | K2: 98 | L2: 60 | M2: 0.612 | N2: 12 | O2: Y | P2: 850 | Q2: 32300 | R2: 83300 | S2: 46277 | T2: 60
A3: GT-JKT-08 | B3: Recycled Denim Jacket | C3: Outerwear | D3: Recycled denim | E3: GRS | F3: Andes Knitworks | G3: Colombia | H3: 35 | I3: 150 | J3: 46 | K3: 118 | L3: 72 | M3: 0.61 | N3: 8 | O3: N | P3: 0 | Q3: 0 | R3: 0 | U3: In GreenThreads catalog; stocked at other stores. Not in the Denver launch assortment.
A4: GT-TEE-01 | B4: Classic Tee | C4: Tops | D4: Organic cotton | E4: GOTS | F4: Delta Organics | G4: India | H4: 45 | I4: 500 | J4: 14.25 | K4: 38 | L4: 23.75 | M4: 0.625 | N4: 24 | O4: Y | P4: 1600 | Q4: 22800 | R4: 60800 | S4: 46262 | T4: 45
A5: GT-POL-05 | B5: Performance Polo | C5: Tops | D5: Recycled pique | E5: GRS | F5: Delta Organics | G5: India | H5: 45 | I5: 400 | J5: 19.5 | K5: 52 | L5: 32.5 | M5: 0.625 | N5: 24 | O5: N | P5: 0 | Q5: 0 | R5: 0 | U5: In GreenThreads catalog; stocked at other stores. Not in the Denver launch assortment.
A6: GT-TNK-06 | B6: Organic Tank Top | C6: Tops | D6: Organic cotton | E6: GOTS | F6: Delta Organics | G6: India | H6: 40 | I6: 500 | J6: 11 | K6: 30 | L6: 19 | M6: 0.633 | N6: 30 | O6: N | P6: 0 | Q6: 0 | R6: 0 | U6: In GreenThreads catalog; stocked at other stores. Not in the Denver launch assortment.
A7: GT-SHT-02 | B7: Active Shorts | C7: Bottoms | D7: Recycled polyester | E7: GRS | F7: Mekong Textile Co. | G7: Vietnam | H7: 60 | I7: 300 | J7: 22 | K7: 58 | L7: 36 | M7: 0.621 | N7: 20 | O7: Y | P7: 1200 | Q7: 26400 | R7: 69600 | S7: 46247 | T7: 30
A8: GT-CHN-07 | B8: Slim Chino | C8: Bottoms | D8: Hemp-cotton blend | E8: OEKO-TEX | F8: Mekong Textile Co. | G8: Vietnam | H8: 60 | I8: 300 | J8: 26 | K8: 68 | L8: 42 | M8: 0.618 | N8: 20 | O8: N | P8: 0 | Q8: 0 | R8: 0 | U8: In GreenThreads catalog; stocked at other stores. Not in the Denver launch assortment.
A9: GT-JOG-03 | B9: Bamboo Joggers | C9: Bottoms | D9: Bamboo viscose | E9: OEKO-TEX | F9: Song Hong Apparel | G9: Vietnam | H9: 65 | I9: 250 | J9: 30 | K9: 78 | L9: 48 | M9: 0.615 | N9: 16 | O9: Y | P9: 950 | Q9: 28500 | R9: 74100 | S9: 46242 | T9: 25

Sheet Austin Daily
A1: Date | B1: Store | C1: Day_Of_Week | D1: Foot_Traffic | E1: Transactions | F1: Units_Sold | G1: Gross_Sales_USD | H1: Returns_USD | I1: Net_Sales_USD | J1: COGS_USD | K1: Gross_Margin_USD | L1: Avg_Transaction_USD
A2: 46083 | B2: Austin-South Congress | C2: Mon | D2: 362 | E2: 74 | F2: 115 | G2: 6764.33 | H2: 275.48 | I2: 6488.85 | J2: 2540.89 | K2: 3947.96 | L2: 87.69
A3: 46084 | B3: Austin-South Congress | C3: Tue | D3: 385 | E3: 72 | F3: 87 | G3: 7141.2 | H3: 314.08 | I3: 6827.12 | J3: 2695.9 | K3: 4131.22 | L3: 94.82
A4: 46085 | B4: Austin-South Congress | C4: Wed | D4: 403 | E4: 86 | F4: 131 | G4: 6367.06 | H4: 395.03 | I4: 5972.03 | J4: 2298.73 | K4: 3673.3 | L4: 69.44
A5: 46086 | B5: Austin-South Congress | C5: Thu | D5: 431 | E5: 90 | F5: 137 | G5: 7548.79 | H5: 449.85 | I5: 7098.94 | J5: 2793.69 | K5: 4305.25 | L5: 78.88
A6: 46087 | B6: Austin-South Congress | C6: Fri | D6: 464 | E6: 99 | F6: 174 | G6: 9481.01 | H6: 550.4 | I6: 8930.61 | J6: 3435.95 | K6: 5494.66 | L6: 90.21
A7: 46088 | B7: Austin-South Congress | C7: Sat | D7: 687 | E7: 144 | F7: 211 | G7: 12312.62 | H7: 811.84 | I7: 11500.78 | J7: 4432.6 | K7: 7068.18 | L7: 79.87
A8: 46089 | B8: Austin-South Congress | C8: Sun | D8: 314 | E8: 87 | F8: 105 | G8: 8414.76 | H8: 188.94 | I8: 8225.82 | J8: 3230.85 | K8: 4994.97 | L8: 94.55
A9: 46090 | B9: Austin-South Congress | C9: Mon | D9: 294 | E9: 60 | F9: 76 | G9: 5774.19 | H9: 378.95 | I9: 5395.24 | J9: 2063.1 | K9: 3332.14 | L9: 89.92
A10: 46091 | B10: Austin-South Congress | C10: Tue | D10: 227 | E10: 57 | F10: 70 | G10: 6354.09 | H10: 157.61 | I10: 6196.48 | J10: 2421.09 | K10: 3775.39 | L10: 108.71
A11: 46092 | B11: Austin-South Congress | C11: Wed | D11: 293 | E11: 76 | F11: 109 | G11: 5998.99 | H11: 297.18 | I11: 5701.81 | J11: 2184.14 | K11: 3517.67 | L11: 75.02
A12: 46093 | B12: Austin-South Congress | C12: Thu | D12: 204 | E12: 61 | F12: 98 | G12: 7587.88 | H12: 165.75 | I12: 7422.13 | J12: 2927.56 | K12: 4494.57 | L12: 121.67
A13: 46094 | B13: Austin-South Congress | C13: Fri | D13: 372 | E13: 85 | F13: 149 | G13: 8028.81 | H13: 355.65 | I13: 7673.16 | J13: 2961.35 | K13: 4711.81 | L13: 90.27
... A135: 46216 | B135: Austin-South Congress | C135: Mon | D135: 164 | E135: 34 | F135: 64 | G135: 3621.24 | H135: 216.24 | I135: 3405 | J135: 1340.97 | K135: 2064.03 | L135: 100.15

Sheet Supplier Reliability
A1: Supplier Reliability — frequency, severity, active exposure
A2: Frequency and severity both reported; they answer different questions. Tier flags severity above 3 days.
A3: As_of_Date: | C3: 46252
A5: Supplier | B5: Country | C5: Received | D5: Late (>0d) | E5: % Late | F5: Avg Days Late | G5: Max | H5: In Transit | I5: Overdue Now | J5: Tier
A6: Song Hong Apparel | B6: Vietnam | C6: =COUNTIFS('Shipments Data'!$D$2:$D$97,$A6,'Shipments Data'!$J$2:$J$97,"Received") -> 12 | D6: =COUNTIFS('Shipments Data'!$D$2:$D$97,$A6,'Shipments Data'!$J$2:$J$97,"Received",'Shipments Data'!$K$2:$K$97,">0") -> 12 | E6: =D6/C6 -> 1 | F6: =AVERAGEIFS('Shipments Data'!$K$2:$K$97,'Shipments Data'!$D$2:$D$97,$A6,'Shipments Data'!$J$2:$J$97,"Received") -> 12.083333 | G6: =_xlfn.MAXIFS('Shipments Data'!$K$2:$K$97,'Shipments Data'!$D$2:$D$97,$A6,'Shipments Data'!$J$2:$J$97,"Received") -> 19 | H6: =COUNTIFS('Shipments Data'!$D$2:$D$97,$A6,'Shipments Data'!$J$2:$J$97,"In transit") -> 3 | I6: =COUNTIFS('Shipments Data'!$D$2:$D$97,$A6,'Shipments Data'!$J$2:$J$97,"In transit",'Shipments Data'!$H$2:$H$97,"<"&$C$3) -> 2 | J6: =IF(F6>3,"At risk","Reliable") -> At risk
A7: Mekong Textile Co. | B7: Vietnam | C7: =COUNTIFS('Shipments Data'!$D$2:$D$97,$A7,'Shipments Data'!$J$2:$J$97,"Received") -> 17 | D7: =COUNTIFS('Shipments Data'!$D$2:$D$97,$A7,'Shipments Data'!$J$2:$J$97,"Received",'Shipments Data'!$K$2:$K$97,">0") -> 17 | E7: =D7/C7 -> 1 | F7: =AVERAGEIFS('Shipments Data'!$K$2:$K$97,'Shipments Data'!$D$2:$D$97,$A7,'Shipments Data'!$J$2:$J$97,"Received") -> 6.9411765 | G7: =_xlfn.MAXIFS('Shipments Data'!$K$2:$K$97,'Shipments Data'!$D$2:$D$97,$A7,'Shipments Data'!$J$2:$J$97,"Received") -> 12 | H7: =COUNTIFS('Shipments Data'!$D$2:$D$97,$A7,'Shipments Data'!$J$2:$J$97,"In transit") -> 9 | I7: =COUNTIFS('Shipments Data'!$D$2:$D$97,$A7,'Shipments Data'!$J$2:$J$97,"In transit",'Shipments Data'!$H$2:$H$97,"<"&$C$3) -> 9 | J7: =IF(F7>3,"At risk","Reliable") -> At risk
A8: Delta Organics | B8: India | C8: =COUNTIFS('Shipments Data'!$D$2:$D$97,$A8,'Shipments Data'!$J$2:$J$97,"Received") -> 28 | D8: =COUNTIFS('Shipments Data'!$D$2:$D$97,$A8,'Shipments Data'!$J$2:$J$97,"Received",'Shipments Data'!$K$2:$K$97,">0") -> 16 | E8: =D8/C8 -> 0.57142857 | F8: =AVERAGEIFS('Shipments Data'!$K$2:$K$97,'Shipments Data'!$D$2:$D$97,$A8,'Shipments Data'!$J$2:$J$97,"Received") -> 0.75 | G8: =_xlfn.MAXIFS('Shipments Data'!$K$2:$K$97,'Shipments Data'!$D$2:$D$97,$A8,'Shipments Data'!$J$2:$J$97,"Received") -> 2 | H8: =COUNTIFS('Shipments Data'!$D$2:$D$97,$A8,'Shipments Data'!$J$2:$J$97,"In transit") -> 4 | I8: =COUNTIFS('Shipments Data'!$D$2:$D$97,$A8,'Shipments Data'!$J$2:$J$97,"In transit",'Shipments Data'!$H$2:$H$97,"<"&$C$3) -> 4 | J8: =IF(F8>3,"At risk","Reliable") -> Reliable
A9: Andes Knitworks | B9: Colombia | C9: =COUNTIFS('Shipments Data'!$D$2:$D$97,$A9,'Shipments Data'!$J$2:$J$97,"Received") -> 23 | D9: =COUNTIFS('Shipments Data'!$D$2:$D$97,$A9,'Shipments Data'!$J$2:$J$97,"Received",'Shipments Data'!$K$2:$K$97,">0") -> 12 | E9: =D9/C9 -> 0.52173913 | F9: =AVERAGEIFS('Shipments Data'!$K$2:$K$97,'Shipments Data'!$D$2:$D$97,$A9,'Shipments Data'!$J$2:$J$97,"Received") -> 0.52173913 | G9: =_xlfn.MAXIFS('Shipments Data'!$K$2:$K$97,'Shipments Data'!$D$2:$D$97,$A9,'Shipments Data'!$J$2:$J$97,"Received") -> 1 | H9: =COUNTIFS('Shipments Data'!$D$2:$D$97,$A9,'Shipments Data'!$J$2:$J$97,"In transit") -> 0 | I9: =COUNTIFS('Shipments Data'!$D$2:$D$97,$A9,'Shipments Data'!$J$2:$J$97,"In transit",'Shipments Data'!$H$2:$H$97,"<"&$C$3) -> 0 | J9: =IF(F9>3,"At risk","Reliable") -> Reliable
A11: Both Vietnam suppliers are late on 100% of completed orders. Song Hong's average rests on 12 orders and is directional.

Sheet Margin Economics
A1: Margin Economics — pricing a day of lost selling
A2: Austin store actuals (134 days) give a company-sourced margin rate, replacing the estimated sell-through used previously.
A4: Metric | B4: Value | C4: Source / formula
A5: Days of Austin data | B5: =COUNT('Austin Daily'!G2:G135) -> 134 | C5: Austin Daily, Mar 2 - Jul 13 2026
A6: Total net sales | B6: =SUM('Austin Daily'!I2:I135) -> 668763.15 | C6: Sum of Net_Sales_USD
A7: Total COGS | B7: =SUM('Austin Daily'!J2:J135) -> 258167.21 | C7: Sum of COGS_USD
A8: Total gross margin | B8: =SUM('Austin Daily'!K2:K135) -> 410595.94 | C8: Sum of Gross_Margin_USD
A9: Realized gross margin % | B9: =B8/B6 -> 0.61396316 | C9: Gross margin divided by net sales
A10: Catalog theoretical margin % | B10: 0.620 | C10: Catalog Margin_Pct average; realized rate closely tracks it
A11: Avg units sold per day | B11: =AVERAGE('Austin Daily'!F2:F135) -> 92.753731 | C11: Average of Units_Sold
A12: Avg gross margin per day | B12: =AVERAGE('Austin Daily'!K2:K135) -> 3064.1488 | C12: Average of Gross_Margin_USD
A13: Gross margin per unit sold | B13: =B8/SUM('Austin Daily'!F2:F135) -> 33.035316 | C13: Total margin divided by total units
A14: Saturday avg gross margin | B14: =AVERAGEIF('Austin Daily'!C2:C135,"Sat",'Austin Daily'!K2:K135) -> 4333.69 | C14: Peak-day rate; opening days run above average
A16: Common unit for the choice set: one day of lost selling at the Austin rate is roughly one average day of gross margin. Austin is an established store, so this is a conservative floor for an opening week, not a forecast.

Sheet Launch Risk
A1: Denver Launch Risk
A2: Launch SKUs mapped to supplier severity, with retail value and margin exposure and carton status.
A4: SKU | B4: Product | C4: Supplier | D4: Units | E4: Retail Value | F4: Unit Margin | G4: Launch Margin | H4: Avg Days Late | I4: Units/Carton | J4: Cartons | K4: Tier | L4: Margin at Risk
A5: GT-HOD-04 | B5: EcoFleece Hoodie | C5: Andes Knitworks | D5: 850 | E5: =D5*98 -> 83300 | F5: 60 | G5: =D5*F5 -> 51000 | H5: =INDEX('Supplier Reliability'!$F$6:$F$9,MATCH(C5,'Supplier Reliability'!$A$6:$A$9,0)) -> 0.52173913 | I5: 12 | J5: =IF(MOD(D5,I5)=0,"Whole","Partial") -> Partial | K5: =INDEX('Supplier Reliability'!$J$6:$J$9,MATCH(C5,'Supplier Reliability'!$A$6:$A$9,0)) -> Reliable | L5: =IF(K5="At risk",G5,0) -> 0
A6: GT-TEE-01 | B6: Classic Tee | C6: Delta Organics | D6: 1600 | E6: =D6*38 -> 60800 | F6: 23.75 | G6: =D6*F6 -> 38000 | H6: =INDEX('Supplier Reliability'!$F$6:$F$9,MATCH(C6,'Supplier Reliability'!$A$6:$A$9,0)) -> 0.75 | I6: 24 | J6: =IF(MOD(D6,I6)=0,"Whole","Partial") -> Partial | K6: =INDEX('Supplier Reliability'!$J$6:$J$9,MATCH(C6,'Supplier Reliability'!$A$6:$A$9,0)) -> Reliable | L6: =IF(K6="At risk",G6,0) -> 0
A7: GT-SHT-02 | B7: Active Shorts | C7: Mekong Textile Co. | D7: 1200 | E7: =D7*58 -> 69600 | F7: 36 | G7: =D7*F7 -> 43200 | H7: =INDEX('Supplier Reliability'!$F$6:$F$9,MATCH(C7,'Supplier Reliability'!$A$6:$A$9,0)) -> 6.9411765 | I7: 20 | J7: =IF(MOD(D7,I7)=0,"Whole","Partial") -> Whole | K7: =INDEX('Supplier Reliability'!$J$6:$J$9,MATCH(C7,'Supplier Reliability'!$A$6:$A$9,0)) -> At risk | L7: =IF(K7="At risk",G7,0) -> 43200
A8: GT-JOG-03 | B8: Bamboo Joggers | C8: Song Hong Apparel | D8: 950 | E8: =D8*78 -> 74100 | F8: 48 | G8: =D8*F8 -> 45600 | H8: =INDEX('Supplier Reliability'!$F$6:$F$9,MATCH(C8,'Supplier Reliability'!$A$6:$A$9,0)) -> 12.083333 | I8: 16 | J8: =IF(MOD(D8,I8)=0,"Whole","Partial") -> Partial | K8: =INDEX('Supplier Reliability'!$J$6:$J$9,MATCH(C8,'Supplier Reliability'!$A$6:$A$9,0)) -> At risk | L8: =IF(K8="At risk",G8,0) -> 45600
C9: TOTAL | D9: =SUM(D5:D8) -> 4600 | E9: =SUM(E5:E8) -> 287800 | G9: =SUM(G5:G8) -> 177800 | L9: =SUM(L5:L8) -> 88800
A10: Retail value at risk: | E10: =SUMIF(K5:K8,"At risk",E5:E8) -> 143700 | G10: =SUMIF(K5:K8,"At risk",G5:G8) -> 88800

Sheet Choice Set
A1: Choice Set & Recommendation
A3: Assumptions (yellow = estimate or judgment, not measured)
A4: Common unit | B4: Days of selling protected, valued at the Austin realized gross-margin rate
A5: Earliest possible open | B5: October 13, 2026 — lease delivery Sept 1 plus the 6-week end of the stated build-out window
A6: Rent clock | B6: Begins October 31 regardless of whether the store has opened (lease §4.2)
A7: Supplier slip | B7: Song Hong ~12 days, Mekong ~7 days, from their own completed-order history
A8: Freight and duty | B8: Wholesale cost is merchandise only; landed COGS is higher, so margin shown is gross of both
A9: Expedite cost | B9: Quote-based; no freight figure is invented in this analysis
A11: Options
A12: Option | B12: Operating move | C12: Priced in the common unit | D12: Trade-off / limitation | E12: Position
A13: A. Hold to Oct 12 | B13: Keep the current plan and promised dates; assume the store is ready. | C13: Protects 0 days. If build-out runs past Oct 12, inventory arrives into a store that cannot open and the full at-risk margin stays exposed. | D13: No cost today, but plans against a date outside the lease's own window. | E13: Reject
A14: B. Control | B14: Confirm the required in-store date with the Store Manager, require ex-factory, container-load, booking and weekly milestones on both Vietnam POs, and test the SOP two-week buffer. | C14: Protects the ability to act; buys roughly 2 weeks of decision time at no freight cost. | D14: Visibility alone creates no backup if a milestone slips. | E14: Partial
A15: C. Gate (recommended) | B15: Adopt B, re-baseline the plan to the confirmed date, secure partial-expedite and backup-source quotes now, and release spend only on a verified trigger. Adopt a standing rule that any supplier averaging over 3 days late gets an automatic two-week buffer. | C15: Protects the opening-weekend selling days on both at-risk SKUs, valued at the Austin margin rate, while paying expedite only if a trigger fires. | D15: Requires cross-functional coordination; final cost stays quote-based until a trigger fires. | E15: APPROVE
A17: Recommendation: Approve Option C, and treat confirming the required in-store date as the first action. Every downstream date, order-by, buffer, expedite trigger, and staffing plan, is calculated from it, and it is the one input no document in any department currently provides.
